2021-07-02T04:25:27.502445+00:00 app[ultroid.1]:                 ----------------------------------------------------------------------
2021-07-02T04:25:27.502445+00:00 app[ultroid.1]: 
2021-07-02T04:26:59.010423+00:00 app[ultroid.1]: [ INFO/2021-07-02 09:56:59,009] telethon.client.telegrambaseclient: Disconnecting borrowed sender for DC 5
2021-07-02T04:26:59.010625+00:00 app[ultroid.1]: [ INFO/2021-07-02 09:56:59,010] telethon.network.mtprotosender: Disconnecting from 91.108.56.180:443/TcpFull...
2021-07-02T04:26:59.015476+00:00 app[ultroid.1]: [ INFO/2021-07-02 09:56:59,015] telethon.network.mtprotosender: Disconnection from 91.108.56.180:443/TcpFull complete!
2021-07-02T04:27:24.202751+00:00 app[ultroid.1]: [ INFO/2021-07-02 09:57:24,202] telethon.client.downloads: Starting direct file download in chunks of 131072 at 0, stride 131072
2021-07-02T04:27:28.748365+00:00 app[ultroid.1]: [ERROR/2021-07-02 09:57:28,746] pyUltroid: Content of the message was not modified (caused by EditMessageRequest)
2021-07-02T04:27:28.748375+00:00 app[ultroid.1]: Traceback (most recent call last):
2021-07-02T04:27:28.748376+00:00 app[ultroid.1]:   File "/usr/local/lib/python3.9/site-packages/pyUltroid/misc/_decorators.py", line 99, in wrapper
2021-07-02T04:27:28.748376+00:00 app[ultroid.1]:     await func(ult)
2021-07-02T04:27:28.748377+00:00 app[ultroid.1]:   File "/root/TeamUltroid/addons/lomgs.py", line 23, in lomgs
2021-07-02T04:27:28.748377+00:00 app[ultroid.1]:     eris = await eor(e, "`...`")
2021-07-02T04:27:28.748378+00:00 app[ultroid.1]:   File "/usr/local/lib/python3.9/site-packages/pyUltroid/misc/_wrappers.py", line 67, in eor
2021-07-02T04:27:28.748378+00:00 app[ultroid.1]:     ok = await event.edit(text, link_preview=link_preview, parse_mode=parse_mode)
2021-07-02T04:27:28.748379+00:00 app[ultroid.1]:   File "/usr/local/lib/python3.9/site-packages/telethon/tl/custom/message.py", line 805, in edit
2021-07-02T04:27:28.748379+00:00 app[ultroid.1]:     return await self._client.edit_message(
2021-07-02T04:27:28.748380+00:00 app[ultroid.1]:   File "/usr/local/lib/python3.9/site-packages/telethon/client/messages.py", line 1165, in edit_message
2021-07-02T04:27:28.748380+00:00 app[ultroid.1]:     msg = self._get_response_message(request, await self(request), entity)
2021-07-02T04:27:28.748381+00:00 app[ultroid.1]:   File "/usr/local/lib/python3.9/site-packages/telethon/client/users.py", line 30, in __call__
2021-07-02T04:27:28.748381+00:00 app[ultroid.1]:     return await self._call(self._sender, request, ordered=ordered)
2021-07-02T04:27:28.748382+00:00 app[ultroid.1]:   File "/usr/local/lib/python3.9/site-packages/telethon/client/users.py", line 79, in _call
2021-07-02T04:27:28.748382+00:00 app[ultroid.1]:     result = await future
2021-07-02T04:27:28.748383+00:00 app[ultroid.1]: telethon.errors.rpcerrorlist.MessageNotModifiedError: Content of the message was not modified (caused by EditMessageRequest)
2021-07-02T04:29:15.028163+00:00 app[ultroid.1]: [ INFO/2021-07-02 09:59:15,027] telethon.client.uploads: Uploading file of 28223 bytes in 1 chunks of 131072
2021-07-02T04:31:57.243272+00:00 app[ultroid.1]: [ INFO/2021-07-02 10:01:57,243] telethon.client.downloads: Starting direct file download in chunks of 131072 at 0, stride 131072
2021-07-02T04:32:07.675323+00:00 app[ultroid.1]: [ INFO/2021-07-02 10:02:07,675] telethon.client.downloads: Starting direct file download in chunks of 131072 at 0, stride 131072
2021-07-02T04:32:11.819411+00:00 app[ultroid.1]: [WARNING/2021-07-02 10:02:11,818] py.warnings: /usr/local/lib/python3.9/site-packages/urllib3/connectionpool.py:1013: InsecureRequestWarning: Unverified HTTPS request is being made to host 'virginia.sessions.logs.heroku.com'. Adding certificate verification is strongly advised. See: https://urllib3.readthedocs.io/en/latest/advanced-usage.html#ssl-warnings
2021-07-02T04:32:11.819419+00:00 app[ultroid.1]:   warnings.warn(
2021-07-02T04:32:11.819420+00:00 app[ultroid.1]: 
2021-07-02T04:32:11.910697+00:00 app[ultroid.1]: [ INFO/2021-07-02 10:02:11,910] telethon.client.uploads: Uploading file of 15001 bytes in 1 chunks of 131072
2021-07-02T04:32:17.259412+00:00 app[ultroid.1]: [ INFO/2021-07-02 10:02:17,259] telethon.client.uploads: Uploading file of 29075 bytes in 1 chunks of 131072
2021-07-02T04:33:50.850114+00:00 app[ultroid.1]: [ INFO/2021-07-02 10:03:50,849] telethon.network.mtprotosender: Connecting to 149.154.175.55:443/TcpFull...
2021-07-02T04:33:50.877861+00:00 app[ultroid.1]: [ INFO/2021-07-02 10:03:50,877] telethon.network.mtprotosender: Connection to 149.154.175.55:443/TcpFull complete!
2021-07-02T04:33:51.081389+00:00 app[ultroid.1]: [ INFO/2021-07-02 10:03:51,061] telethon.network.mtprotosender: Disconnecting from 149.154.175.55:443/TcpFull...
2021-07-02T04:33:51.082239+00:00 app[ultroid.1]: [ INFO/2021-07-02 10:03:51,081] telethon.network.mtprotosender: Disconnection from 149.154.175.55:443/TcpFull complete!
2021-07-02T04:33:51.083187+00:00 app[ultroid.1]: [ INFO/2021-07-02 10:03:51,082] telethon.network.mtprotosender: Connecting to 149.154.175.55:443/TcpFull...
2021-07-02T04:33:51.114139+00:00 app[ultroid.1]: [ INFO/2021-07-02 10:03:51,113] telethon.network.mtprotosender: Connection to 149.154.175.55:443/TcpFull complete!
2021-07-02T04:33:51.422346+00:00 app[ultroid.1]: [ INFO/2021-07-02 10:03:51,422] telethon.network.mtprotosender: Disconnecting from 149.154.175.55:443/TcpFull...
2021-07-02T04:33:51.438371+00:00 app[ultroid.1]: [ INFO/2021-07-02 10:03:51,438] telethon.network.mtprotosender: Disconnection from 149.154.175.55:443/TcpFull complete!
2021-07-02T04:33:51.439400+00:00 app[ultroid.1]: [ INFO/2021-07-02 10:03:51,439] telethon.client.uploads: Uploading file of 48325 bytes in 1 chunks of 131072
2021-07-02T04:34:08.991306+00:00 app[ultroid.1]: [ INFO/2021-07-02 10:04:08,991] telethon.client.downloads: Starting direct file download in chunks of 131072 at 0, stride 131072
2021-07-02T04:36:23.907325+00:00 app[ultroid.1]: [ERROR/2021-07-02 10:06:23,906] pyUltroid: The bot did not answer to the callback query in time (caused by GetInlineBotResultsRequest)
2021-07-02T04:36:23.907336+00:00 app[ultroid.1]: Traceback (most recent call last):
2021-07-02T04:36:23.907337+00:00 app[ultroid.1]:   File "/usr/local/lib/python3.9/site-packages/pyUltroid/misc/_decorators.py", line 99, in wrapper
2021-07-02T04:36:23.907338+00:00 app[ultroid.1]:     await func(ult)
2021-07-02T04:36:23.907338+00:00 app[ultroid.1]:   File "/root/TeamUltroid/addons/inlinefun.py", line 43, in tweet
2021-07-02T04:36:23.907338+00:00 app[ultroid.1]:     results = await ultroid_bot.inline_query("twitterstatusbot", text)
2021-07-02T04:36:23.907339+00:00 app[ultroid.1]:   File "/usr/local/lib/python3.9/site-packages/telethon/client/bots.py", line 64, in inline_query
2021-07-02T04:36:23.907339+00:00 app[ultroid.1]:     result = await self(functions.messages.GetInlineBotResultsRequest(
2021-07-02T04:36:23.907340+00:00 app[ultroid.1]:   File "/usr/local/lib/python3.9/site-packages/telethon/client/users.py", line 30, in __call__
2021-07-02T04:36:23.907341+00:00 app[ultroid.1]:     return await self._call(self._sender, request, ordered=ordered)
2021-07-02T04:36:23.907341+00:00 app[ultroid.1]:   File "/usr/local/lib/python3.9/site-packages/telethon/client/users.py", line 79, in _call
2021-07-02T04:36:23.907342+00:00 app[ultroid.1]:     result = await future
2021-07-02T04:36:23.907343+00:00 app[ultroid.1]: telethon.errors.rpcerrorlist.BotResponseTimeoutError: The bot did not answer to the callback query in time (caused by GetInlineBotResultsRequest)
2021-07-02T04:37:02.114886+00:00 app[ultroid.1]: [ERROR/2021-07-02 10:07:02,114] pyUltroid: The bot did not answer to the callback query in time (caused by GetInlineBotResultsRequest)
2021-07-02T04:37:02.114900+00:00 app[ultroid.1]: Traceback (most recent call last):
2021-07-02T04:37:02.114901+00:00 app[ultroid.1]:   File "/usr/local/lib/python3.9/site-packages/pyUltroid/misc/_decorators.py", line 99, in wrapper
2021-07-02T04:37:02.114902+00:00 app[ultroid.1]:     await func(ult)
2021-07-02T04:37:02.114902+00:00 app[ultroid.1]:   File "/root/TeamUltroid/addons/inlinefun.py", line 43, in tweet
2021-07-02T04:37:02.114903+00:00 app[ultroid.1]:     results = await ultroid_bot.inline_query("twitterstatusbot", text)
2021-07-02T04:37:02.114903+00:00 app[ultroid.1]:   File "/usr/local/lib/python3.9/site-packages/telethon/client/bots.py", line 64, in inline_query
2021-07-02T04:37:02.114904+00:00 app[ultroid.1]:     result = await self(functions.messages.GetInlineBotResultsRequest(
2021-07-02T04:37:02.114904+00:00 app[ultroid.1]:   File "/usr/local/lib/python3.9/site-packages/telethon/client/users.py", line 30, in __call__
2021-07-02T04:37:02.114905+00:00 app[ultroid.1]:     return await self._call(self._sender, request, ordered=ordered)
2021-07-02T04:37:02.114905+00:00 app[ultroid.1]:   File "/usr/local/lib/python3.9/site-packages/telethon/client/users.py", line 79, in _call
2021-07-02T04:37:02.114905+00:00 app[ultroid.1]:     result = await future
2021-07-02T04:37:02.114907+00:00 app[ultroid.1]: telethon.errors.rpcerrorlist.BotResponseTimeoutError: The bot did not answer to the callback query in time (caused by GetInlineBotResultsRequest)
2021-07-02T04:37:35.087548+00:00 app[ultroid.1]: [ INFO/2021-07-02 10:07:35,087] telethon.client.downloads: Starting direct file download in chunks of 131072 at 0, stride 131072
2021-07-02T04:37:57.614151+00:00 app[ultroid.1]: [ INFO/2021-07-02 10:07:57,613] telethon.client.downloads: Starting direct file download in chunks of 131072 at 0, stride 131072
2021-07-02T04:39:08.145600+00:00 app[ultroid.1]: [ INFO/2021-07-02 10:09:08,145] telethon.client.downloads: Starting direct file download in chunks of 131072 at 0, stride 131072
2021-07-02T04:40:25.001886+00:00 app[ultroid.1]: [ INFO/2021-07-02 10:10:25,001] telethon.client.downloads: Starting direct file download in chunks of 131072 at 0, stride 131072
2021-07-02T04:44:16.414043+00:00 app[ultroid.1]: [ INFO/2021-07-02 10:14:16,413] telethon.client.downloads: Starting direct file download in chunks of 131072 at 0, stride 131072
2021-07-02T04:48:31.767158+00:00 app[ultroid.1]: [ INFO/2021-07-02 10:18:31,766] telethon.client.downloads: Starting direct file download in chunks of 131072 at 0, stride 131072
2021-07-02T04:54:01.767657+00:00 app[ultroid.1]: [ERROR/2021-07-02 10:24:01,765] telethon.client.updates: Unhandled exception on say
2021-07-02T04:54:01.767667+00:00 app[ultroid.1]: Traceback (most recent call last):
2021-07-02T04:54:01.767668+00:00 app[ultroid.1]:   File "/usr/local/lib/python3.9/site-packages/telethon/client/updates.py", line 454, in _dispatch_update
2021-07-02T04:54:01.767668+00:00 app[ultroid.1]:     await callback(event)
2021-07-02T04:54:01.767669+00:00 app[ultroid.1]:   File "/root/TeamUltroid/addons/ibutton.py", line 250, in say
2021-07-02T04:54:01.767669+00:00 app[ultroid.1]:     await e.answer([res])
2021-07-02T04:54:01.767670+00:00 app[ultroid.1]:   File "/usr/local/lib/python3.9/site-packages/telethon/events/inlinequery.py", line 228, in answer
2021-07-02T04:54:01.767670+00:00 app[ultroid.1]:     return await self._client(
2021-07-02T04:54:01.767671+00:00 app[ultroid.1]:   File "/usr/local/lib/python3.9/site-packages/telethon/client/users.py", line 30, in __call__
2021-07-02T04:54:01.767671+00:00 app[ultroid.1]:     return await self._call(self._sender, request, ordered=ordered)
2021-07-02T04:54:01.767672+00:00 app[ultroid.1]:   File "/usr/local/lib/python3.9/site-packages/telethon/client/users.py", line 79, in _call
2021-07-02T04:54:01.767672+00:00 app[ultroid.1]:     result = await future
2021-07-02T04:54:01.767673+00:00 app[ultroid.1]: telethon.errors.rpcerrorlist.MessageEmptyError: Empty or invalid UTF-8 message was sent (caused by SetInlineBotResultsRequest)
2021-07-02T04:58:29.043935+00:00 app[ultroid.1]: [ INFO/2021-07-02 10:28:29,043] telethon.client.downloads: Starting direct file download in chunks of 131072 at 0, stride 131072
2021-07-02T11:40:19.869198+00:00 app[ultroid.1]: [ INFO/2021-07-02 17:10:19,868] telethon.client.downloads: Starting direct file download in chunks of 131072 at 0, stride 131072
2021-07-02T11:40:28.132561+00:00 app[ultroid.1]: [ERROR/2021-07-02 17:10:28,132] pyUltroid: name 'emoji' is not defined
2021-07-02T11:40:28.132569+00:00 app[ultroid.1]: Traceback (most recent call last):
2021-07-02T11:40:28.132588+00:00 app[ultroid.1]:   File "/usr/local/lib/python3.9/site-packages/pyUltroid/misc/_decorators.py", line 99, in wrapper
2021-07-02T11:40:28.132589+00:00 app[ultroid.1]:     await func(ult)
2021-07-02T11:40:28.132589+00:00 app[ultroid.1]:   File "/root/TeamUltroid/addons/text_to_gif.py", line 32, in ttg
2021-07-02T11:40:28.132590+00:00 app[ultroid.1]:     args = remove_emoji(args)
2021-07-02T11:40:28.132590+00:00 app[ultroid.1]:   File "/root/TeamUltroid/addons/text_to_gif.py", line 17, in remove_emoji
2021-07-02T11:40:28.132591+00:00 app[ultroid.1]:     return emoji.get_emoji_regexp().sub(u'', string)
2021-07-02T11:40:28.132592+00:00 app[ultroid.1]: NameError: name 'emoji' is not defined
2021-07-02T11:41:55.394688+00:00 app[ultroid.1]: [ INFO/2021-07-02 17:11:55,394] telethon.client.downloads: Starting direct file download in chunks of 131072 at 0, stride 131072
2021-07-02T11:44:00.251121+00:00 app[ultroid.1]: [ INFO/2021-07-02 17:14:00,250] telethon.client.downloads: Starting direct file download in chunks of 131072 at 0, stride 131072
2021-07-02T11:44:43.727802+00:00 app[ultroid.1]: [ INFO/2021-07-02 17:14:43,727] telethon.client.downloads: Starting direct file download in chunks of 131072 at 0, stride 131072
