2021-07-01T13:46:21.864132+00:00 app[ultroid.1]: NameError: name 'query' is not defined
2021-07-01T13:54:18.981989+00:00 app[ultroid.1]: [ERROR/2021-07-01 19:24:18,981] telethon.client.updates: Unhandled exception on query_ibutton
2021-07-01T13:54:18.982006+00:00 app[ultroid.1]: Traceback (most recent call last):
2021-07-01T13:54:18.982018+00:00 app[ultroid.1]:   File "/usr/local/lib/python3.9/site-packages/telethon/client/updates.py", line 454, in _dispatch_update
2021-07-01T13:54:18.982019+00:00 app[ultroid.1]:     await callback(event)
2021-07-01T13:54:18.982019+00:00 app[ultroid.1]:   File "<string>", line 9, in query_ibutton
2021-07-01T13:54:18.982021+00:00 app[ultroid.1]: TypeError: photo() got an unexpected keyword argument 'description'
2021-07-01T13:54:25.384711+00:00 app[ultroid.1]: [WARNING/2021-07-01 19:24:25,384] py.warnings: /usr/local/lib/python3.9/site-packages/urllib3/connectionpool.py:1013: InsecureRequestWarning: Unverified HTTPS request is being made to host 'virginia.sessions.logs.heroku.com'. Adding certificate verification is strongly advised. See: https://urllib3.readthedocs.io/en/latest/advanced-usage.html#ssl-warnings
2021-07-01T13:54:25.384751+00:00 app[ultroid.1]:   warnings.warn(
2021-07-01T13:54:25.384751+00:00 app[ultroid.1]: 
2021-07-01T13:54:25.455895+00:00 app[ultroid.1]: [ INFO/2021-07-01 19:24:25,455] telethon.client.uploads: Uploading file of 12332 bytes in 1 chunks of 131072
2021-07-01T13:55:25.566675+00:00 app[ultroid.1]: [ERROR/2021-07-01 19:25:25,566] telethon.client.updates: Unhandled exception on query_ibutton
2021-07-01T13:55:25.566721+00:00 app[ultroid.1]: Traceback (most recent call last):
2021-07-01T13:55:25.566722+00:00 app[ultroid.1]:   File "/usr/local/lib/python3.9/site-packages/telethon/client/updates.py", line 454, in _dispatch_update
2021-07-01T13:55:25.566723+00:00 app[ultroid.1]:     await callback(event)
2021-07-01T13:55:25.566723+00:00 app[ultroid.1]:   File "<string>", line 9, in query_ibutton
2021-07-01T13:55:25.566724+00:00 app[ultroid.1]: TypeError: photo() got an unexpected keyword argument 'title'
2021-07-01T13:55:34.192094+00:00 app[ultroid.1]: [WARNING/2021-07-01 19:25:34,191] py.warnings: /usr/local/lib/python3.9/site-packages/urllib3/connectionpool.py:1013: InsecureRequestWarning: Unverified HTTPS request is being made to host 'virginia.sessions.logs.heroku.com'. Adding certificate verification is strongly advised. See: https://urllib3.readthedocs.io/en/latest/advanced-usage.html#ssl-warnings
2021-07-01T13:55:34.192130+00:00 app[ultroid.1]:   warnings.warn(
2021-07-01T13:55:34.192132+00:00 app[ultroid.1]: 
2021-07-01T13:55:34.278530+00:00 app[ultroid.1]: [ INFO/2021-07-01 19:25:34,278] telethon.client.uploads: Uploading file of 12048 bytes in 1 chunks of 131072
2021-07-01T13:56:17.910546+00:00 app[ultroid.1]: [ERROR/2021-07-01 19:26:17,909] telethon.client.updates: Unhandled exception on query_ibutton
2021-07-01T13:56:17.910565+00:00 app[ultroid.1]: Traceback (most recent call last):
2021-07-01T13:56:17.910565+00:00 app[ultroid.1]:   File "/usr/local/lib/python3.9/site-packages/telethon/client/updates.py", line 454, in _dispatch_update
2021-07-01T13:56:17.910566+00:00 app[ultroid.1]:     await callback(event)
2021-07-01T13:56:17.910566+00:00 app[ultroid.1]:   File "<string>", line 9, in query_ibutton
2021-07-01T13:56:17.910568+00:00 app[ultroid.1]: TypeError: photo() got an unexpected keyword argument 'url'
2021-07-01T13:56:52.551305+00:00 app[ultroid.1]: [ERROR/2021-07-01 19:26:52,550] telethon.client.updates: Unhandled exception on query_ibutton
2021-07-01T13:56:52.551316+00:00 app[ultroid.1]: Traceback (most recent call last):
2021-07-01T13:56:52.551325+00:00 app[ultroid.1]:   File "/usr/local/lib/python3.9/site-packages/telethon/client/updates.py", line 454, in _dispatch_update
2021-07-01T13:56:52.551327+00:00 app[ultroid.1]:     await callback(event)
2021-07-01T13:56:52.551327+00:00 app[ultroid.1]:   File "<string>", line 9, in query_ibutton
2021-07-01T13:56:52.551328+00:00 app[ultroid.1]: TypeError: photo() got an unexpected keyword argument 'url'
2021-07-01T13:56:57.721114+00:00 app[ultroid.1]: [WARNING/2021-07-01 19:26:57,720] py.warnings: /usr/local/lib/python3.9/site-packages/urllib3/connectionpool.py:1013: InsecureRequestWarning: Unverified HTTPS request is being made to host 'virginia.sessions.logs.heroku.com'. Adding certificate verification is strongly advised. See: https://urllib3.readthedocs.io/en/latest/advanced-usage.html#ssl-warnings
2021-07-01T13:56:57.721129+00:00 app[ultroid.1]:   warnings.warn(
2021-07-01T13:56:57.721130+00:00 app[ultroid.1]: 
2021-07-01T13:56:57.801843+00:00 app[ultroid.1]: [ INFO/2021-07-01 19:26:57,801] telethon.client.uploads: Uploading file of 11657 bytes in 1 chunks of 131072
2021-07-01T14:00:41.756592+00:00 app[ultroid.1]: [ERROR/2021-07-01 19:30:41,755] telethon.client.updates: Unhandled exception on query_ibutton
2021-07-01T14:00:41.756604+00:00 app[ultroid.1]: Traceback (most recent call last):
2021-07-01T14:00:41.756604+00:00 app[ultroid.1]:   File "/usr/local/lib/python3.9/site-packages/telethon/tl/custom/inlinebuilder.py", line 300, in document
2021-07-01T14:00:41.756605+00:00 app[ultroid.1]:     fh = utils.get_input_document(file)
2021-07-01T14:00:41.756605+00:00 app[ultroid.1]:   File "/usr/local/lib/python3.9/site-packages/telethon/utils.py", line 344, in get_input_document
2021-07-01T14:00:41.756605+00:00 app[ultroid.1]:     return get_input_document(document.media)
2021-07-01T14:00:41.756606+00:00 app[ultroid.1]:   File "/usr/local/lib/python3.9/site-packages/telethon/utils.py", line 346, in get_input_document
2021-07-01T14:00:41.756606+00:00 app[ultroid.1]:     _raise_cast_fail(document, 'InputDocument')
2021-07-01T14:00:41.756607+00:00 app[ultroid.1]:   File "/usr/local/lib/python3.9/site-packages/telethon/utils.py", line 138, in _raise_cast_fail
2021-07-01T14:00:41.756607+00:00 app[ultroid.1]:     raise TypeError('Cannot cast {} to any kind of {}.'.format(
2021-07-01T14:00:41.756608+00:00 app[ultroid.1]: TypeError: Cannot cast MessageMediaPhoto to any kind of InputDocument.
2021-07-01T14:00:41.756609+00:00 app[ultroid.1]: 
2021-07-01T14:00:41.756609+00:00 app[ultroid.1]: During handling of the above exception, another exception occurred:
2021-07-01T14:00:41.756609+00:00 app[ultroid.1]: 
2021-07-01T14:00:41.756610+00:00 app[ultroid.1]: Traceback (most recent call last):
2021-07-01T14:00:41.756610+00:00 app[ultroid.1]:   File "/usr/local/lib/python3.9/site-packages/telethon/client/updates.py", line 454, in _dispatch_update
2021-07-01T14:00:41.756611+00:00 app[ultroid.1]:     await callback(event)
2021-07-01T14:00:41.756611+00:00 app[ultroid.1]:   File "<string>", line 18, in query_ibutton
2021-07-01T14:00:41.756611+00:00 app[ultroid.1]:   File "/usr/local/lib/python3.9/site-packages/telethon/events/inlinequery.py", line 221, in answer
2021-07-01T14:00:41.756611+00:00 app[ultroid.1]:     results = [x.result() for x in futures]
2021-07-01T14:00:41.756612+00:00 app[ultroid.1]:   File "/usr/local/lib/python3.9/site-packages/telethon/events/inlinequery.py", line 221, in <listcomp>
2021-07-01T14:00:41.756612+00:00 app[ultroid.1]:     results = [x.result() for x in futures]
2021-07-01T14:00:41.756612+00:00 app[ultroid.1]:   File "/usr/local/lib/python3.9/site-packages/telethon/tl/custom/inlinebuilder.py", line 314, in document
2021-07-01T14:00:41.756612+00:00 app[ultroid.1]:     r = await self._client(functions.messages.UploadMediaRequest(
2021-07-01T14:00:41.756612+00:00 app[ultroid.1]:   File "/usr/local/lib/python3.9/site-packages/telethon/client/users.py", line 79, in _call
2021-07-01T14:00:41.756613+00:00 app[ultroid.1]:     result = await future
2021-07-01T14:00:41.756613+00:00 app[ultroid.1]: telethon.errors.rpcerrorlist.MediaInvalidError: Media invalid (caused by UploadMediaRequest)
2021-07-01T14:00:47.982202+00:00 app[ultroid.1]: [WARNING/2021-07-01 19:30:47,981] py.warnings: /usr/local/lib/python3.9/site-packages/urllib3/connectionpool.py:1013: InsecureRequestWarning: Unverified HTTPS request is being made to host 'virginia.sessions.logs.heroku.com'. Adding certificate verification is strongly advised. See: https://urllib3.readthedocs.io/en/latest/advanced-usage.html#ssl-warnings
2021-07-01T14:00:47.982212+00:00 app[ultroid.1]:   warnings.warn(
2021-07-01T14:00:47.982213+00:00 app[ultroid.1]: 
2021-07-01T14:00:48.040565+00:00 app[ultroid.1]: [ INFO/2021-07-01 19:30:48,040] telethon.client.uploads: Uploading file of 11692 bytes in 1 chunks of 131072
2021-07-01T14:16:05.226314+00:00 app[ultroid.1]: [ INFO/2021-07-01 19:46:05,225] telethon.network.mtprotosender: Connecting to 149.154.175.51:443/TcpFull...
2021-07-01T14:16:05.274339+00:00 app[ultroid.1]: [ INFO/2021-07-01 19:46:05,274] telethon.network.mtprotosender: Connection to 149.154.175.51:443/TcpFull complete!
2021-07-01T14:16:09.342828+00:00 app[ultroid.1]: [ INFO/2021-07-01 19:46:09,342] telethon.network.mtprotosender: Disconnecting from 149.154.175.51:443/TcpFull...
2021-07-01T14:16:09.343444+00:00 app[ultroid.1]: [ INFO/2021-07-01 19:46:09,343] telethon.network.mtprotosender: Disconnection from 149.154.175.51:443/TcpFull complete!
2021-07-01T14:16:09.344403+00:00 app[ultroid.1]: [ INFO/2021-07-01 19:46:09,344] telethon.client.uploads: Uploading file of 83112 bytes in 1 chunks of 131072
2021-07-01T14:24:02.681899+00:00 app[ultroid.1]: [ERROR/2021-07-01 19:54:02,680] telethon.client.updates: Unhandled exception on query_ibutton
2021-07-01T14:24:02.681910+00:00 app[ultroid.1]: Traceback (most recent call last):
2021-07-01T14:24:02.681920+00:00 app[ultroid.1]:   File "/usr/local/lib/python3.9/site-packages/telethon/tl/custom/inlinebuilder.py", line 300, in document
2021-07-01T14:24:02.681921+00:00 app[ultroid.1]:     fh = utils.get_input_document(file)
2021-07-01T14:24:02.681921+00:00 app[ultroid.1]:   File "/usr/local/lib/python3.9/site-packages/telethon/utils.py", line 344, in get_input_document
2021-07-01T14:24:02.681922+00:00 app[ultroid.1]:     return get_input_document(document.media)
2021-07-01T14:24:02.681922+00:00 app[ultroid.1]:   File "/usr/local/lib/python3.9/site-packages/telethon/utils.py", line 346, in get_input_document
2021-07-01T14:24:02.681922+00:00 app[ultroid.1]:     _raise_cast_fail(document, 'InputDocument')
2021-07-01T14:24:02.681923+00:00 app[ultroid.1]:   File "/usr/local/lib/python3.9/site-packages/telethon/utils.py", line 138, in _raise_cast_fail
2021-07-01T14:24:02.681924+00:00 app[ultroid.1]:     raise TypeError('Cannot cast {} to any kind of {}.'.format(
2021-07-01T14:24:02.681925+00:00 app[ultroid.1]: TypeError: Cannot cast MessageMediaPhoto to any kind of InputDocument.
2021-07-01T14:24:02.681926+00:00 app[ultroid.1]: 
2021-07-01T14:24:02.681927+00:00 app[ultroid.1]: During handling of the above exception, another exception occurred:
2021-07-01T14:24:02.681927+00:00 app[ultroid.1]: 
2021-07-01T14:24:02.681927+00:00 app[ultroid.1]: Traceback (most recent call last):
2021-07-01T14:24:02.681928+00:00 app[ultroid.1]:   File "/usr/local/lib/python3.9/site-packages/telethon/client/updates.py", line 454, in _dispatch_update
2021-07-01T14:24:02.681929+00:00 app[ultroid.1]:     await callback(event)
2021-07-01T14:24:02.681929+00:00 app[ultroid.1]:   File "<string>", line 18, in query_ibutton
2021-07-01T14:24:02.681929+00:00 app[ultroid.1]:   File "/usr/local/lib/python3.9/site-packages/telethon/events/inlinequery.py", line 221, in answer
2021-07-01T14:24:02.681930+00:00 app[ultroid.1]:     results = [x.result() for x in futures]
2021-07-01T14:24:02.681930+00:00 app[ultroid.1]:   File "/usr/local/lib/python3.9/site-packages/telethon/events/inlinequery.py", line 221, in <listcomp>
2021-07-01T14:24:02.681930+00:00 app[ultroid.1]:     results = [x.result() for x in futures]
2021-07-01T14:24:02.681931+00:00 app[ultroid.1]:   File "/usr/local/lib/python3.9/site-packages/telethon/tl/custom/inlinebuilder.py", line 314, in document
2021-07-01T14:24:02.681931+00:00 app[ultroid.1]:     r = await self._client(functions.messages.UploadMediaRequest(
2021-07-01T14:24:02.681931+00:00 app[ultroid.1]:   File "/usr/local/lib/python3.9/site-packages/telethon/client/users.py", line 79, in _call
2021-07-01T14:24:02.681932+00:00 app[ultroid.1]:     result = await future
2021-07-01T14:24:02.681932+00:00 app[ultroid.1]: telethon.errors.rpcerrorlist.MediaInvalidError: Media invalid (caused by UploadMediaRequest)
