2021-06-22T08:47:02.814924+00:00 app[worker.1]:     return self.execute_command('GET', name)
2021-06-22T08:47:02.814928+00:00 app[worker.1]:   File "/usr/local/lib/python3.9/site-packages/redis/client.py", line 898, in execute_command
2021-06-22T08:47:02.815214+00:00 app[worker.1]:     conn = self.connection or pool.get_connection(command_name, **options)
2021-06-22T08:47:02.815220+00:00 app[worker.1]:   File "/usr/local/lib/python3.9/site-packages/redis/connection.py", line 1192, in get_connection
2021-06-22T08:47:02.815620+00:00 app[worker.1]:     connection.connect()
2021-06-22T08:47:02.815624+00:00 app[worker.1]:   File "/usr/local/lib/python3.9/site-packages/redis/connection.py", line 563, in connect
2021-06-22T08:47:02.815853+00:00 app[worker.1]:     raise ConnectionError(self._error_message(e))
2021-06-22T08:47:02.815874+00:00 app[worker.1]: redis.exceptions.ConnectionError: Error -3 connecting to redis-15850.c266.us-east-1-3.ec2.cloud.redislabs.com:15850. Temporary failure in name resolution.
2021-06-22T08:47:21.478974+00:00 app[api]: Scaled to web@0:Free worker@1:Free by user kumarvishal79501@gmail.com
2021-06-22T08:47:21.985398+00:00 heroku[web.1]: State changed from starting to down
2021-06-22T08:47:33.910690+00:00 heroku[worker.1]: Starting process with command `/bin/sh -c bash\ resources/startup/startup.sh`
2021-06-22T08:47:34.591253+00:00 heroku[worker.1]: State changed from starting to up
2021-06-22T08:47:34.600254+00:00 heroku[worker.1]: Idling
2021-06-22T08:47:34.606389+00:00 heroku[worker.1]: State changed from up to down
2021-06-22T08:47:34.619725+00:00 heroku[worker.1]: Idling because quota is exhausted
2021-06-22T08:47:39.278714+00:00 heroku[web.1]: Starting process with command `/bin/sh -c python\ vcstarter.py`
2021-06-22T08:47:41.653317+00:00 app[worker.1]: 
2021-06-22T08:47:41.653356+00:00 app[worker.1]:             ┏┳┓╋┏┓╋╋╋╋┏┓┏┓
2021-06-22T08:47:41.653356+00:00 app[worker.1]:             ┃┃┣┓┃┗┳┳┳━╋╋┛┃
2021-06-22T08:47:41.653357+00:00 app[worker.1]:             ┃┃┃┗┫┏┫┏┫╋┃┃╋┃
2021-06-22T08:47:41.653357+00:00 app[worker.1]:             ┗━┻━┻━┻┛┗━┻┻━┛
2021-06-22T08:47:41.653357+00:00 app[worker.1]: 
2021-06-22T08:47:41.653481+00:00 app[worker.1]:       Visit @TheUltroid for updates!!
2021-06-22T08:47:41.653482+00:00 app[worker.1]: 
2021-06-22T08:47:41.653487+00:00 app[worker.1]: 
2021-06-22T08:47:43.438119+00:00 heroku[web.1]: Process exited with status 1
2021-06-22T08:47:43.232033+00:00 app[web.1]: WARNING:root:ERROR - unpack requires a buffer of 275 bytes
2021-06-22T08:47:50.447274+00:00 app[worker.1]: Traceback (most recent call last):
2021-06-22T08:47:50.447303+00:00 app[worker.1]:   File "/usr/local/lib/python3.9/site-packages/redis/connection.py", line 559, in connect
2021-06-22T08:47:50.447616+00:00 app[worker.1]:     sock = self._connect()
2021-06-22T08:47:50.447616+00:00 app[worker.1]:   File "/usr/local/lib/python3.9/site-packages/redis/connection.py", line 584, in _connect
2021-06-22T08:47:50.447965+00:00 app[worker.1]:     for res in socket.getaddrinfo(self.host, self.port, self.socket_type,
2021-06-22T08:47:50.447985+00:00 app[worker.1]:   File "/usr/local/lib/python3.9/socket.py", line 953, in getaddrinfo
2021-06-22T08:47:50.448374+00:00 app[worker.1]:     for res in _socket.getaddrinfo(host, port, family, type, proto, flags):
2021-06-22T08:47:50.448401+00:00 app[worker.1]: socket.gaierror: [Errno -3] Temporary failure in name resolution
2021-06-22T08:47:50.448401+00:00 app[worker.1]: 
2021-06-22T08:47:50.448402+00:00 app[worker.1]: During handling of the above exception, another exception occurred:
2021-06-22T08:47:50.448402+00:00 app[worker.1]: 
2021-06-22T08:47:50.448405+00:00 app[worker.1]: Traceback (most recent call last):
2021-06-22T08:47:50.448426+00:00 app[worker.1]:   File "/usr/local/lib/python3.9/runpy.py", line 188, in _run_module_as_main
2021-06-22T08:47:50.448569+00:00 app[worker.1]:     mod_name, mod_spec, code = _get_module_details(mod_name, _Error)
2021-06-22T08:47:50.448569+00:00 app[worker.1]:   File "/usr/local/lib/python3.9/runpy.py", line 147, in _get_module_details
2021-06-22T08:47:50.448693+00:00 app[worker.1]:     return _get_module_details(pkg_main_name, error)
2021-06-22T08:47:50.448693+00:00 app[worker.1]:   File "/usr/local/lib/python3.9/runpy.py", line 111, in _get_module_details
2021-06-22T08:47:50.448806+00:00 app[worker.1]:     __import__(pkg_name)
2021-06-22T08:47:50.448807+00:00 app[worker.1]:   File "/usr/local/lib/python3.9/site-packages/pyUltroid/__init__.py", line 48, in <module>
2021-06-22T08:47:50.448919+00:00 app[worker.1]:     BOT_MODE = Var.BOT_MODE or udB.get("BOT_MODE")
2021-06-22T08:47:50.448921+00:00 app[worker.1]:   File "/usr/local/lib/python3.9/site-packages/redis/client.py", line 1606, in get
2021-06-22T08:47:50.449521+00:00 app[worker.1]:     return self.execute_command('GET', name)
2021-06-22T08:47:50.449545+00:00 app[worker.1]:   File "/usr/local/lib/python3.9/site-packages/redis/client.py", line 898, in execute_command
2021-06-22T08:47:50.449994+00:00 app[worker.1]:     conn = self.connection or pool.get_connection(command_name, **options)
2021-06-22T08:47:50.449997+00:00 app[worker.1]:   File "/usr/local/lib/python3.9/site-packages/redis/connection.py", line 1192, in get_connection
2021-06-22T08:47:50.450585+00:00 app[worker.1]:     connection.connect()
2021-06-22T08:47:50.450606+00:00 app[worker.1]:   File "/usr/local/lib/python3.9/site-packages/redis/connection.py", line 563, in connect
2021-06-22T08:47:50.450970+00:00 app[worker.1]:     raise ConnectionError(self._error_message(e))
2021-06-22T08:47:50.450972+00:00 app[worker.1]: redis.exceptions.ConnectionError: Error -3 connecting to redis-15850.c266.us-east-1-3.ec2.cloud.redislabs.com:15850. Temporary failure in name resolution.